[2023-03-22T08:04:48.065+0400] {taskinstance.py:1083} INFO - Dependencies all met for <TaskInstance: data_gcp_4.local_to_gcs_task scheduled__2023-03-21T00:00:00+00:00 [queued]>
[2023-03-22T08:04:48.068+0400] {taskinstance.py:1083} INFO - Dependencies all met for <TaskInstance: data_gcp_4.local_to_gcs_task scheduled__2023-03-21T00:00:00+00:00 [queued]>
[2023-03-22T08:04:48.068+0400] {taskinstance.py:1279} INFO - 
--------------------------------------------------------------------------------
[2023-03-22T08:04:48.068+0400] {taskinstance.py:1280} INFO - Starting attempt 2 of 2
[2023-03-22T08:04:48.068+0400] {taskinstance.py:1281} INFO - 
--------------------------------------------------------------------------------
[2023-03-22T08:04:48.080+0400] {taskinstance.py:1300} INFO - Executing <Task(PythonOperator): local_to_gcs_task> on 2023-03-21 00:00:00+00:00
[2023-03-22T08:04:48.083+0400] {standard_task_runner.py:55} INFO - Started process 495372 to run task
[2023-03-22T08:04:48.085+0400] {standard_task_runner.py:82} INFO - Running: ['airflow', 'tasks', 'run', 'data_gcp_4', 'local_to_gcs_task', 'scheduled__2023-03-21T00:00:00+00:00', '--job-id', '42', '--raw', '--subdir', 'DAGS_FOLDER/data_gsp.py', '--cfg-path', '/tmp/tmpw7zseyxs']
[2023-03-22T08:04:48.086+0400] {standard_task_runner.py:83} INFO - Job 42: Subtask local_to_gcs_task
[2023-03-22T08:04:48.111+0400] {task_command.py:388} INFO - Running <TaskInstance: data_gcp_4.local_to_gcs_task scheduled__2023-03-21T00:00:00+00:00 [running]> on host civispc
[2023-03-22T08:04:48.136+0400] {taskinstance.py:1507} INFO - Exporting the following env vars:
AIRFLOW_CTX_DAG_OWNER=airflow
AIRFLOW_CTX_DAG_ID=data_gcp_4
AIRFLOW_CTX_TASK_ID=local_to_gcs_task
AIRFLOW_CTX_EXECUTION_DATE=2023-03-21T00:00:00+00:00
AIRFLOW_CTX_TRY_NUMBER=2
AIRFLOW_CTX_DAG_RUN_ID=scheduled__2023-03-21T00:00:00+00:00
[2023-03-22T08:04:48.187+0400] {taskinstance.py:1768} ERROR - Task failed with exception
Traceback (most recent call last):
  File "/home/civis/anaconda3/lib/python3.9/site-packages/airflow/operators/python.py", line 175, in execute
    return_value = self.execute_callable()
  File "/home/civis/anaconda3/lib/python3.9/site-packages/airflow/operators/python.py", line 192, in execute_callable
    return self.python_callable(*self.op_args, **self.op_kwargs)
  File "/home/civis/git/de_zoomcamp_project/airflow/dags/data_gsp.py", line 103, in upload_to_gcs
    pload_files(blob)
NameError: name 'pload_files' is not defined
[2023-03-22T08:04:48.189+0400] {taskinstance.py:1318} INFO - Marking task as FAILED. dag_id=data_gcp_4, task_id=local_to_gcs_task, execution_date=20230321T000000, start_date=20230322T040448, end_date=20230322T040448
[2023-03-22T08:04:48.200+0400] {standard_task_runner.py:100} ERROR - Failed to execute job 42 for task local_to_gcs_task (name 'pload_files' is not defined; 495372)
[2023-03-22T08:04:48.216+0400] {local_task_job.py:208} INFO - Task exited with return code 1
[2023-03-22T08:04:48.223+0400] {taskinstance.py:2578} INFO - 0 downstream tasks scheduled from follow-on schedule check
