[2023-03-22T07:53:06.057+0400] {taskinstance.py:1083} INFO - Dependencies all met for <TaskInstance: data_gcp_3.local_to_gcs_task manual__2023-03-22T03:52:55.071289+00:00 [queued]>
[2023-03-22T07:53:06.060+0400] {taskinstance.py:1083} INFO - Dependencies all met for <TaskInstance: data_gcp_3.local_to_gcs_task manual__2023-03-22T03:52:55.071289+00:00 [queued]>
[2023-03-22T07:53:06.060+0400] {taskinstance.py:1279} INFO - 
--------------------------------------------------------------------------------
[2023-03-22T07:53:06.060+0400] {taskinstance.py:1280} INFO - Starting attempt 1 of 2
[2023-03-22T07:53:06.060+0400] {taskinstance.py:1281} INFO - 
--------------------------------------------------------------------------------
[2023-03-22T07:53:06.072+0400] {taskinstance.py:1300} INFO - Executing <Task(PythonOperator): local_to_gcs_task> on 2023-03-22 03:52:55.071289+00:00
[2023-03-22T07:53:06.075+0400] {standard_task_runner.py:55} INFO - Started process 473719 to run task
[2023-03-22T07:53:06.076+0400] {standard_task_runner.py:82} INFO - Running: ['airflow', 'tasks', 'run', 'data_gcp_3', 'local_to_gcs_task', 'manual__2023-03-22T03:52:55.071289+00:00', '--job-id', '34', '--raw', '--subdir', 'DAGS_FOLDER/data_gsp.py', '--cfg-path', '/tmp/tmp24xf3voz']
[2023-03-22T07:53:06.077+0400] {standard_task_runner.py:83} INFO - Job 34: Subtask local_to_gcs_task
[2023-03-22T07:53:06.102+0400] {task_command.py:388} INFO - Running <TaskInstance: data_gcp_3.local_to_gcs_task manual__2023-03-22T03:52:55.071289+00:00 [running]> on host civispc
[2023-03-22T07:53:06.134+0400] {taskinstance.py:1507} INFO - Exporting the following env vars:
AIRFLOW_CTX_DAG_OWNER=airflow
AIRFLOW_CTX_DAG_ID=data_gcp_3
AIRFLOW_CTX_TASK_ID=local_to_gcs_task
AIRFLOW_CTX_EXECUTION_DATE=2023-03-22T03:52:55.071289+00:00
AIRFLOW_CTX_TRY_NUMBER=1
AIRFLOW_CTX_DAG_RUN_ID=manual__2023-03-22T03:52:55.071289+00:00
[2023-03-22T07:53:06.187+0400] {taskinstance.py:1768} ERROR - Task failed with exception
Traceback (most recent call last):
  File "/home/civis/anaconda3/lib/python3.9/site-packages/airflow/operators/python.py", line 175, in execute
    return_value = self.execute_callable()
  File "/home/civis/anaconda3/lib/python3.9/site-packages/airflow/operators/python.py", line 192, in execute_callable
    return self.python_callable(*self.op_args, **self.op_kwargs)
  File "/home/civis/git/de_zoomcamp_project/airflow/dags/data_gsp.py", line 96, in upload_to_gcs
    blob.upload_from_filename("pq")
  File "/home/civis/anaconda3/lib/python3.9/site-packages/google/cloud/storage/blob.py", line 2681, in upload_from_filename
    with open(filename, "rb") as file_obj:
IsADirectoryError: [Errno 21] Is a directory: 'pq'
[2023-03-22T07:53:06.189+0400] {taskinstance.py:1318} INFO - Marking task as UP_FOR_RETRY. dag_id=data_gcp_3, task_id=local_to_gcs_task, execution_date=20230322T035255, start_date=20230322T035306, end_date=20230322T035306
[2023-03-22T07:53:06.200+0400] {standard_task_runner.py:100} ERROR - Failed to execute job 34 for task local_to_gcs_task ([Errno 21] Is a directory: 'pq'; 473719)
[2023-03-22T07:53:06.207+0400] {local_task_job.py:208} INFO - Task exited with return code 1
[2023-03-22T07:53:06.212+0400] {taskinstance.py:2578} INFO - 0 downstream tasks scheduled from follow-on schedule check
