[2023-03-22T08:08:06.837+0400] {taskinstance.py:1083} INFO - Dependencies all met for <TaskInstance: data_gcp_6.local_to_gcs_task scheduled__2023-03-21T00:00:00+00:00 [queued]>
[2023-03-22T08:08:06.840+0400] {taskinstance.py:1083} INFO - Dependencies all met for <TaskInstance: data_gcp_6.local_to_gcs_task scheduled__2023-03-21T00:00:00+00:00 [queued]>
[2023-03-22T08:08:06.840+0400] {taskinstance.py:1279} INFO - 
--------------------------------------------------------------------------------
[2023-03-22T08:08:06.840+0400] {taskinstance.py:1280} INFO - Starting attempt 1 of 2
[2023-03-22T08:08:06.841+0400] {taskinstance.py:1281} INFO - 
--------------------------------------------------------------------------------
[2023-03-22T08:08:06.853+0400] {taskinstance.py:1300} INFO - Executing <Task(PythonOperator): local_to_gcs_task> on 2023-03-21 00:00:00+00:00
[2023-03-22T08:08:06.856+0400] {standard_task_runner.py:55} INFO - Started process 501977 to run task
[2023-03-22T08:08:06.857+0400] {standard_task_runner.py:82} INFO - Running: ['airflow', 'tasks', 'run', 'data_gcp_6', 'local_to_gcs_task', 'scheduled__2023-03-21T00:00:00+00:00', '--job-id', '51', '--raw', '--subdir', 'DAGS_FOLDER/data_gsp.py', '--cfg-path', '/tmp/tmpdytsoskg']
[2023-03-22T08:08:06.858+0400] {standard_task_runner.py:83} INFO - Job 51: Subtask local_to_gcs_task
[2023-03-22T08:08:06.888+0400] {task_command.py:388} INFO - Running <TaskInstance: data_gcp_6.local_to_gcs_task scheduled__2023-03-21T00:00:00+00:00 [running]> on host civispc
[2023-03-22T08:08:06.922+0400] {taskinstance.py:1507} INFO - Exporting the following env vars:
AIRFLOW_CTX_DAG_OWNER=airflow
AIRFLOW_CTX_DAG_ID=data_gcp_6
AIRFLOW_CTX_TASK_ID=local_to_gcs_task
AIRFLOW_CTX_EXECUTION_DATE=2023-03-21T00:00:00+00:00
AIRFLOW_CTX_TRY_NUMBER=1
AIRFLOW_CTX_DAG_RUN_ID=scheduled__2023-03-21T00:00:00+00:00
[2023-03-22T08:08:06.973+0400] {taskinstance.py:1768} ERROR - Task failed with exception
Traceback (most recent call last):
  File "/home/civis/anaconda3/lib/python3.9/site-packages/airflow/operators/python.py", line 175, in execute
    return_value = self.execute_callable()
  File "/home/civis/anaconda3/lib/python3.9/site-packages/airflow/operators/python.py", line 192, in execute_callable
    return self.python_callable(*self.op_args, **self.op_kwargs)
  File "/home/civis/git/de_zoomcamp_project/airflow/dags/data_gsp.py", line 105, in upload_to_gcs
    upload_files(blob)
  File "/home/civis/git/de_zoomcamp_project/airflow/dags/data_gsp.py", line 75, in upload_files
    files = [f for f in listdir("localFolder") if isfile(join(localFolder, f))]
FileNotFoundError: [Errno 2] No such file or directory: 'localFolder'
[2023-03-22T08:08:06.975+0400] {taskinstance.py:1318} INFO - Marking task as UP_FOR_RETRY. dag_id=data_gcp_6, task_id=local_to_gcs_task, execution_date=20230321T000000, start_date=20230322T040806, end_date=20230322T040806
[2023-03-22T08:08:06.987+0400] {standard_task_runner.py:100} ERROR - Failed to execute job 51 for task local_to_gcs_task ([Errno 2] No such file or directory: 'localFolder'; 501977)
[2023-03-22T08:08:07.029+0400] {local_task_job.py:208} INFO - Task exited with return code 1
[2023-03-22T08:08:07.038+0400] {taskinstance.py:2578} INFO - 0 downstream tasks scheduled from follow-on schedule check
